Workbook
Name mgPERg: #REF!
Name minPERday: #REF!

Sheet Field data
A1: Calculation of chamber volume used in field gas sampling
A2: Chamber dimensions and parameter variables
A3: Date of gas sampling: | B3: 44743
A4: 15.24 cm = 6" | B4: 30.48 cm = 1' | C4: 60.96 cm = 2' | D4: 91.44 cm = 3'
C6: CHAMBER HEIGHT | I6: Chamber Radius | J6: Total chamber volume | L6: Area covered | M6: Floodwater height
A7: Plot | B7: Trt | C7: Lid | D7: Collar | E7: Collar Extension | H7: TOTAL
E8: 1 | F8: 2 | G8: 3
C9: cm | D9: cm | E9: cm | F9: cm | G9: cm | H9: cm | I9: cm | J9: cm3 | K9: L | L9: cm2 | M9: cm
A10: 101 | C10: 7.62 | D10: =AVERAGE(B38:B41) -> -9 | E10: 30.48 | H10: =SUM(C10:G10) -> 29.1 | I10: 14.75 | J10: =3.141592654*(I10*I10)*H10 -> 19889.639 | K10: =J10/1000 -> 19.889639 | L10: =3.141592654*(I10*I10) -> 683.49275 | M10: =AVERAGE(B48:B51) -> 0
A11: 102 | C11: 7.62 | D11: =AVERAGE(C38:C41) -> -12.475 | E11: 30.48 | H11: =SUM(C11:G11) -> 25.625 | I11: 14.75 | J11: =3.141592654*(I11*I11)*H11 -> 17514.502 | K11: =J11/1000 -> 17.514502 | L11: =3.141592654*(I11*I11) -> 683.49275 | M11: =AVERAGE(C48:C51) -> 0
A12: 103 | C12: 7.62 | D12: =AVERAGE(D38:D41) -> -10.5 | E12: 30.48 | H12: =SUM(C12:G12) -> 27.6 | I12: 14.75 | J12: =3.141592654*(I12*I12)*H12 -> 18864.4 | K12: =J12/1000 -> 18.8644 | L12: =3.141592654*(I12*I12) -> 683.49275 | M12: =AVERAGE(D48:D51) -> 0
A13: 104 | C13: 7.62 | D13: =AVERAGE(E38:E41) -> -8.75 | E13: 30.48 | H13: =SUM(C13:G13) -> 29.35 | I13: 14.75 | J13: =3.141592654*(I13*I13)*H13 -> 20060.512 | K13: =J13/1000 -> 20.060512 | L13: =3.141592654*(I13*I13) -> 683.49275 | M13: =AVERAGE(E48:E51) -> 0
A14: 105 | C14: 7.62 | D14: =AVERAGE(F38:F41) -> -10.5 | E14: 30.48 | H14: =SUM(C14:G14) -> 27.6 | I14: 14.75 | J14: =3.141592654*(I14*I14)*H14 -> 18864.4 | K14: =J14/1000 -> 18.8644 | L14: =3.141592654*(I14*I14) -> 683.49275 | M14: =AVERAGE(F48:F51) -> 0
A15: 106 | C15: 7.62 | D15: =AVERAGE(G38:G41) -> -10.75 | E15: 30.48 | H15: =SUM(C15:G15) -> 27.35 | I15: 14.75 | J15: =3.141592654*(I15*I15)*H15 -> 18693.527 | K15: =J15/1000 -> 18.693527 | L15: =3.141592654*(I15*I15) -> 683.49275 | M15: =AVERAGE(G48:G51) -> 0
A16: 201 | C16: 7.62 | D16: =AVERAGE(H38:H41) -> -10.375 | E16: 30.48 | H16: =SUM(C16:G16) -> 27.725 | I16: 14.75 | J16: =3.141592654*(I16*I16)*H16 -> 18949.837 | K16: =J16/1000 -> 18.949837 | L16: =3.141592654*(I16*I16) -> 683.49275 | M16: =AVERAGE(H48:H51) -> #DIV/0!
A17: 202 | C17: 7.62 | D17: =AVERAGE(I38:I41) -> -8.625 | E17: 30.48 | H17: =SUM(C17:G17) -> 29.475 | I17: 14.75 | J17: =3.141592654*(I17*I17)*H17 -> 20145.949 | K17: =J17/1000 -> 20.145949 | L17: =3.141592654*(I17*I17) -> 683.49275 | M17: =AVERAGE(I48:I51) -> #DIV/0!
A18: 203 | C18: 7.62 | D18: =AVERAGE(J38:J41) -> -8.25 | E18: 30.48 | H18: =SUM(C18:G18) -> 29.85 | I18: 14.75 | J18: =3.141592654*(I18*I18)*H18 -> 20402.259 | K18: =J18/1000 -> 20.402259 | L18: =3.141592654*(I18*I18) -> 683.49275 | M18: =AVERAGE(J48:J51) -> #DIV/0!
A19: 204 | C19: 7.62 | D19: =AVERAGE(K38:K41) -> -7 | E19: 30.48 | H19: =SUM(C19:G19) -> 31.1 | I19: 14.75 | J19: =3.141592654*(I19*I19)*H19 -> 21256.625 | K19: =J19/1000 -> 21.256625 | L19: =3.141592654*(I19*I19) -> 683.49275 | M19: =AVERAGE(K48:K51) -> #DIV/0!
A20: 205 | C20: 7.62 | D20: =AVERAGE(L38:L41) -> -7 | E20: 30.48 | H20: =SUM(C20:G20) -> 31.1 | I20: 14.75 | J20: =3.141592654*(I20*I20)*H20 -> 21256.625 | K20: =J20/1000 -> 21.256625 | L20: =3.141592654*(I20*I20) -> 683.49275 | M20: =AVERAGE(L48:L51) -> #DIV/0!
A21: 206 | C21: 7.62 | D21: =AVERAGE(M38:M41) -> -7.35 | E21: 30.48 | H21: =SUM(C21:G21) -> 30.75 | I21: 14.75 | J21: =3.141592654*(I21*I21)*H21 -> 21017.402 | K21: =J21/1000 -> 21.017402 | L21: =3.141592654*(I21*I21) -> 683.49275 | M21: =AVERAGE(M48:M51) -> #DIV/0!
C25: 402 | D25: 409 | E25: 505 | F25: 512 | G25: 601 | H25: 608 | I25: 209 | J25: 307 | K25: K1
B35: Collar to water, cm (headspace height)
B36: F I E L D I D | F36: F I E L D I D | J36: F I E L D I D
A37: Replicate | B37: 101 | C37: 102 | D37: 103 | E37: 104 | F37: 105 | G37: 106 | H37: 201 | I37: 202 | J37: 203 | K37: 204 | L37: 205 | M37: 206
A38: 1 | B38: -9 | C38: -12.5 | D38: -10.5 | E38: -9 | F38: -10.5 | G38: -10.5 | H38: -10.5 | I38: -9 | J38: -8 | K38: -7 | L38: -7 | M38: -7.5
A39: 2 | B39: -9 | C39: -13 | E39: -9 | G39: -10.5 | H39: -10.5 | I39: -8.5 | J39: -8 | K39: -7 | M39: -7.5
A40: 3 | C40: -12.2 | E40: -8.5 | G40: -11 | H40: -10 | I40: -8.5 | J40: -8.5 | M40: -7.2
A41: 4 | C41: -12.2 | E41: -8.5 | G41: -11 | H41: -10.5 | I41: -8.5 | J41: -8.5 | M41: -7.2
A42: MEAN | B42: =AVERAGE(B38:B41) -> -9 | C42: =AVERAGE(C38:C41) -> -12.475 | D42: =AVERAGE(D38:D41) -> -10.5 | E42: =AVERAGE(E38:E41) -> -8.75 | F42: =AVERAGE(F38:F41) -> -10.5 | G42: =AVERAGE(G38:G41) -> -10.75 | H42: =AVERAGE(H38:H41) -> -10.375 | I42: =AVERAGE(I38:I41) -> -8.625 | ... M42: =AVERAGE(M38:M41) -> -7.35
B45: Floodwater height, cm
B46: FIELD ID | F46: F I E L D I D | J46: F I E L D I D
A47: Replicate | B47: 402 | C47: 409 | D47: 505 | E47: 512 | F47: 601 | G47: 608 | H47: 209 | I47: 307 | J47: K1 | K47: Extra | L47: Extra | M47: Extra
A48: 1 | B48: 0 | C48: 0 | D48: 0 | E48: 0 | F48: 0 | G48: 0
A49: 2
A50: 3
A51: 4
A52: MEAN | B52: =AVERAGE(B48:B51) -> 0 | C52: =AVERAGE(C48:C51) -> 0 | D52: =AVERAGE(D48:D51) -> 0 | E52: =AVERAGE(E48:E51) -> 0 | F52: =AVERAGE(F48:F51) -> 0 | G52: =AVERAGE(G48:G51) -> 0 | H52: =AVERAGE(H48:H51) -> #DIV/0! | I52: =AVERAGE(I48:I51) -> #DIV/0! | ... M52: =AVERAGE(M48:M51) -> #DIV/0!
I56: 0-5 cm soil depth | K56: T E M P E R A T U R E
A57: 5-15 cm soil depth | I57: Plot | J57: Trt | K57: Soil Temperature | M57: Mean Soil Temperature, oC
A58: Plot | B58: Trt | C58: Soil Temperature | E58: Mean Soil Temperature, oC | K58: 1 | L58: 2
...

Sheet GC rawdata
A1: Copy data here
A2: Site | B2: Date | C2: Plot | D2: Time | E2: CH4 (ppm) | F2: N2O (ppm) | H2: N2O
A3: RES | C3: 101 | D3: 0 | E3: 3.5296729 | F3: 0.3328208 | H3: Plot | I3: Trt | J3: Air Temperature, oC | N3: CONCENTRATION, ppm (mol/mol) | R3: Volume of 1 mol of air inside chamber at sampling, L | V3: N2O CONCENTRATION, mg L-1
A4: RES | C4: 101 | D4: 21 | E4: 6.0410903 | F4: 0.33761189
A5: RES | C5: 101 | D5: 42 | E5: 7.9290858 | F5: 0.34391489 | J5: 0 | K5: 21 | L5: 42 | M5: 63 | N5: 0 | O5: 21 | P5: 42 | Q5: 63 | R5: 0 | S5: 21 | T5: 42 | U5: 63 | V5: 0 | W5: 21 | X5: 42 | Y5: 63
A6: RES | C6: 101 | D6: 63 | E6: 10.754811 | F6: 0.34982969 | J6: Copy data here
A7: RES | C7: 102 | D7: 0 | E7: 2.378823 | F7: 0.34120777 | H7: 101 | J7: 24.7 | K7: 27.9 | L7: 28.9 | M7: 29.5 | N7: =F3 -> 0.3328208 | O7: =F4 -> 0.33761189 | P7: =F5 -> 0.34391489 | Q7: =F6 -> 0.34982969 | R7: =(((760*22.4)*(273+J7))/(760*273)) -> 24.426667 | S7: =(((760*22.4)*(273+K7))/(760*273)) -> 24.689231 | T7: =(((760*22.4)*(273+L7))/(760*273)) -> 24.771282 | U7: =(((760*22.4)*(273+M7))/(760*273)) -> 24.820513 | V7: =((N7/(R7))*(0.044014)) -> 0.0005997042 | W7: =((O7/(S7))*(0.044014)) -> 0.00060186767 | X7: =((P7/(T7))*(0.044014)) -> 0.00061107333 | Y7: =((Q7/(U7))*(0.044014)) -> 0.00062034996 | AA7: 24.7 | AB7: 25.6 | AC7: 25.8 | AD7: 24.7
A8: RES | C8: 102 | D8: 21 | E8: 3.4053826 | F8: 0.34550851 | H8: 102 | J8: 26 | K8: 28.5 | L8: 29.4 | M8: 30.2 | N8: =F7 -> 0.34120777 | O8: =F8 -> 0.34550851 | P8: =F9 -> 0.3457639 | Q8: =F10 -> 0.3606071 | R8: =(((760*22.4)*(273+J8))/(760*273)) -> 24.533333 | S8: =(((760*22.4)*(273+K8))/(760*273)) -> 24.738462 | T8: =(((760*22.4)*(273+L8))/(760*273)) -> 24.812308 | U8: =(((760*22.4)*(273+M8))/(760*273)) -> 24.877949 | V8: =((N8/(R8))*(0.044014)) -> 0.00061214342 | W8: =((O8/(S8))*(0.044014)) -> 0.00061471938 | X8: =((P8/(T8))*(0.044014)) -> 0.00061334288 | Y8: =((Q8/(U8))*(0.044014)) -> 0.00063798511 | AA8: 27.9 | AB8: 27.3 | AC8: 28 | AD8: 28
A9: RES | C9: 102 | D9: 42 | E9: 4.5042955 | F9: 0.3457639 | H9: 103 | J9: 25.4 | K9: 27.9 | L9: 29 | M9: 29.2 | N9: =F11 -> 0.34920654 | O9: =F12 -> 0.36151628 | P9: =F13 -> 0.35616333 | Q9: =F14 -> 0.3613937 | R9: =(((760*22.4)*(273+J9))/(760*273)) -> 24.484103 | S9: =(((760*22.4)*(273+K9))/(760*273)) -> 24.689231 | T9: =(((760*22.4)*(273+L9))/(760*273)) -> 24.779487 | U9: =(((760*22.4)*(273+M9))/(760*273)) -> 24.795897 | V9: =((N9/(R9))*(0.044014)) -> 0.00062775332 | W9: =((O9/(S9))*(0.044014)) -> 0.00064448252 | X9: =((P9/(T9))*(0.044014)) -> 0.00063262701 | Y9: =((Q9/(U9))*(0.044014)) -> 0.0006414925 | AA9: 28.9 | AB9: 29.3 | AC9: 28.9 | AD9: 29.3
A10: RES | C10: 102 | D10: 63 | E10: 5.8722058 | F10: 0.3606071 | H10: 104 | J10: 25.6 | K10: 27.3 | L10: 29.3 | M10: 29.1 | N10: =F15 -> 0.35974899 | O10: =F16 -> 0.41324784 | P10: =F17 -> 0.36554121 | Q10: =F18 -> 0.37262059 | R10: =(((760*22.4)*(273+J10))/(760*273)) -> 24.500513 | S10: =(((760*22.4)*(273+K10))/(760*273)) -> 24.64 | T10: =(((760*22.4)*(273+L10))/(760*273)) -> 24.804103 | U10: =(((760*22.4)*(273+M10))/(760*273)) -> 24.787692 | V10: =((N10/(R10))*(0.044014)) -> 0.00064627187 | W10: =((O10/(S10))*(0.044014)) -> 0.00073817738 | X10: =((P10/(T10))*(0.044014)) -> 0.00064863991 | Y10: =((Q10/(U10))*(0.044014)) -> 0.00066163975 | AA10: 29.5 | AB10: 29.1 | AC10: 29.1 | AD10: 29.6
A11: RES | C11: 103 | D11: 0 | E11: 2.3005595 | F11: 0.34920654 | H11: 105 | J11: 25.9 | K11: 27.8 | L11: 29.4 | M11: 29.3 | N11: =F19 -> 0.32214554 | O11: =F20 -> 0.34456868 | P11: =F21 -> 0.34979905 | Q11: =F22 -> 0.35675584 | R11: =(((760*22.4)*(273+J11))/(760*273)) -> 24.525128 | S11: =(((760*22.4)*(273+K11))/(760*273)) -> 24.681026 | T11: =(((760*22.4)*(273+L11))/(760*273)) -> 24.812308 | U11: =(((760*22.4)*(273+M11))/(760*273)) -> 24.804103 | V11: =((N11/(R11))*(0.044014)) -> 0.00057813822 | W11: =((O11/(S11))*(0.044014)) -> 0.0006144739 | X11: =((P11/(T11))*(0.044014)) -> 0.00062050074 | Y11: =((Q11/(U11))*(0.044014)) -> 0.00063305057 | AA11: 26 | AB11: 25.9 | AC11: 24.9 | AD11: 24.9
A12: RES | C12: 103 | D12: 21 | E12: 3.2219916 | F12: 0.36151628 | H12: 106 | J12: 27.2 | K12: 28.8 | L12: 29.7 | M12: 29.2 | N12: =F23 -> 0.34507946 | O12: =F24 -> 0.33534404 | P12: =F25 -> 0.34065613 | Q12: =F26 -> 0.35639829 | R12: =(((760*22.4)*(273+J12))/(760*273)) -> 24.631795 | S12: =(((760*22.4)*(273+K12))/(760*273)) -> 24.763077 | T12: =(((760*22.4)*(273+L12))/(760*273)) -> 24.836923 | U12: =(((760*22.4)*(273+M12))/(760*273)) -> 24.795897 | V12: =((N12/(R12))*(0.044014)) -> 0.00061661472 | W12: =((O12/(S12))*(0.044014)) -> 0.00059604194 | X12: =((P12/(T12))*(0.044014)) -> 0.00060368342 | Y12: =((Q12/(U12))*(0.044014)) -> 0.0006326254 | AA12: 28.5 | AB12: 27.8 | AC12: 30.5 | AD12: 28.8
A13: RES | C13: 103 | D13: 42 | E13: 4.1174552 | F13: 0.35616333 | H13: 201 | J13: 25.8 | K13: 28 | L13: 28.9 | M13: 29.1 | N13: =F27 -> 0.34763335 | O13: =F28 -> 0.34926784 | P13: =F29 -> 0.35089211 | Q13: =F30 -> 0.36114852 | R13: =(((760*22.4)*(273+J13))/(760*273)) -> 24.516923 | S13: =(((760*22.4)*(273+K13))/(760*273)) -> 24.697436 | T13: =(((760*22.4)*(273+L13))/(760*273)) -> 24.771282 | U13: =(((760*22.4)*(273+M13))/(760*273)) -> 24.787692 | V13: =((N13/(R13))*(0.044014)) -> 0.00062408868 | W13: =((O13/(S13))*(0.044014)) -> 0.0006224401 | X13: =((P13/(T13))*(0.044014)) -> 0.00062347057 | Y13: =((Q13/(U13))*(0.044014)) -> 0.0006412695 | AA13: 29.4 | AB13: 29.4 | AC13: 30.8 | AD13: 30
A14: RES | C14: 103 | D14: 63 | E14: 4.999666 | F14: 0.3613937 | H14: 202 | J14: 24.9 | K14: 30.5 | L14: 30.8 | M14: 34.3 | N14: =F31 -> 0.35848226 | O14: =F32 -> 0.34743925 | P14: =F33 -> 0.36318142 | Q14: =F34 -> 0.36280344 | R14: =(((760*22.4)*(273+J14))/(760*273)) -> 24.443077 | S14: =(((760*22.4)*(273+K14))/(760*273)) -> 24.902564 | T14: =(((760*22.4)*(273+L14))/(760*273)) -> 24.927179 | U14: =(((760*22.4)*(273+M14))/(760*273)) -> 25.214359 | V14: =((N14/(R14))*(0.044014)) -> 0.0006455095 | W14: =((O14/(S14))*(0.044014)) -> 0.00061408099 | X14: =((P14/(T14))*(0.044014)) -> 0.00064127059 | Y14: =((Q14/(U14))*(0.044014)) -> 0.00063330703 | AA14: 30.2 | AB14: 29.3 | AC14: 34.3 | AD14: 30.7
A15: RES | C15: 104 | D15: 0 | E15: 2.286053 | F15: 0.35974899 | H15: 203 | J15: 25 | K15: 28.4 | L15: 29.5 | M15: 29.8 | N15: =F35 -> 0.35772631 | O15: =F36 -> 0.36167973 | P15: =F37 -> 0.36000438 | Q15: =F38 -> 0.35913606 | R15: =(((760*22.4)*(273+J15))/(760*273)) -> 24.451282 | S15: =(((760*22.4)*(273+K15))/(760*273)) -> 24.730256 | T15: =(((760*22.4)*(273+L15))/(760*273)) -> 24.820513 | U15: =(((760*22.4)*(273+M15))/(760*273)) -> 24.845128 | V15: =((N15/(R15))*(0.044014)) -> 0.00064393212 | W15: =((O15/(S15))*(0.044014)) -> 0.00064370427 | X15: =((P15/(T15))*(0.044014)) -> 0.00063839265 | Y15: =((Q15/(U15))*(0.044014)) -> 0.0006362219 | AA15: 25.4 | AB15: 27.2 | AC15: 25 | AD15: 24.9
A16: RES | C16: 104 | D16: 21 | E16: 2.2735165 | F16: 0.41324784 | H16: 204 | J16: 24.7 | K16: 28 | L16: 29.3 | M16: 29.6 | N16: =F39 -> 0.35938123 | O16: =F40 -> 0.36131197 | P16: =F41 -> 0.36326314 | Q16: =F42 -> 0.36003503 | R16: =(((760*22.4)*(273+J16))/(760*273)) -> 24.426667 | S16: =(((760*22.4)*(273+K16))/(760*273)) -> 24.697436 | T16: =(((760*22.4)*(273+L16))/(760*273)) -> 24.804103 | U16: =(((760*22.4)*(273+M16))/(760*273)) -> 24.828718 | V16: =((N16/(R16))*(0.044014)) -> 0.000647563 | W16: =((O16/(S16))*(0.044014)) -> 0.0006439043 | X16: =((P16/(T16))*(0.044014)) -> 0.00064459756 | Y16: =((Q16/(U16))*(0.044014)) -> 0.00063823601 | AA16: 27.9 | AB16: 28.8 | AC16: 28.4 | AD16: 27.8
A17: RES | C17: 104 | D17: 42 | E17: 3.8686954 | F17: 0.36554121 | H17: 205 | J17: 24.9 | K17: 28.8 | L17: 30 | M17: 30.7 | N17: =F43 -> 0.36728807 | O17: =F44 -> 0.35826774 | P17: =F45 -> 0.36224159 | Q17: =F46 -> 0.36975002 | R17: =(((760*22.4)*(273+J17))/(760*273)) -> 24.443077 | S17: =(((760*22.4)*(273+K17))/(760*273)) -> 24.763077 | T17: =(((760*22.4)*(273+L17))/(760*273)) -> 24.861538 | U17: =(((760*22.4)*(273+M17))/(760*273)) -> 24.918974 | V17: =((N17/(R17))*(0.044014)) -> 0.00066136588 | W17: =((O17/(S17))*(0.044014)) -> 0.00063678663 | X17: =((P17/(T17))*(0.044014)) -> 0.00064129987 | Y17: =((Q17/(U17))*(0.044014)) -> 0.00065308376 | AA17: 29 | AB17: 29.7 | AC17: 29.5 | AD17: 28.8
A18: RES | C18: 104 | D18: 63 | E18: 4.5023255 | F18: 0.37262059 | H18: 206 | J18: 24.9 | K18: 27.8 | L18: 28.8 | M18: 30.1 | N18: =F47 -> 0.36871825 | O18: =F48 -> 0.35973878 | P18: =F49 -> 0.36386586 | Q18: =F50 -> 0.368422 | R18: =(((760*22.4)*(273+J18))/(760*273)) -> 24.443077 | S18: =(((760*22.4)*(273+K18))/(760*273)) -> 24.681026 | T18: =(((760*22.4)*(273+L18))/(760*273)) -> 24.763077 | U18: =(((760*22.4)*(273+M18))/(760*273)) -> 24.869744 | V18: =((N18/(R18))*(0.044014)) -> 0.00066394117 | W18: =((O18/(S18))*(0.044014)) -> 0.00064152693 | X18: =((P18/(T18))*(0.044014)) -> 0.00064673676 | Y18: =((Q18/(U18))*(0.044014)) -> 0.00065202626 | AA18: 29.2 | AB18: 29.2 | AC18: 29.8 | AD18: 30.1
A19: RES | C19: 105 | D19: 0 | E19: 2.7660215 | F19: 0.32214554
A20: RES | C20: 105 | D20: 21 | E20: 4.7129386 | F20: 0.34456868
A21: RES | C21: 105 | D21: 42 | E21: 6.3887092 | F21: 0.34979905 | H21: CH4
A22: RES | C22: 105 | D22: 63 | E22: 7.9842464 | F22: 0.35675584 | H22: Plot | I22: Trt | J22: Air Temperature, oC | N22: CONCENTRATION, ppm (mol/mol) | R22: Volume of 1 mol of air inside chamber at sampling, L | V22: CH4 CONCENTRATION, mg L-1
A23: RES | C23: 106 | D23: 0 | E23: 2.6082408 | F23: 0.34507946
A24: RES | C24: 106 | D24: 21 | E24: 4.1239026 | F24: 0.33534404 | J24: 0 | K24: 21 | L24: 42 | M24: 63 | N24: 0 | O24: 21 | P24: 42 | Q24: 63 | R24: 0 | S24: 21 | T24: 42 | U24: 63 | V24: 0 | W24: 21 | X24: 42 | Y24: 63
A25: RES | C25: 106 | D25: 42 | E25: 5.9062334 | F25: 0.34065613
A26: RES | C26: 106 | D26: 63 | E26: 7.3722865 | F26: 0.35639829 | H26: 101 | J26: =J7 -> 24.7 | K26: =K7 -> 27.9 | L26: =L7 -> 28.9 | M26: =M7 -> 29.5 | N26: =E3 -> 3.5296729 | O26: =E4 -> 6.0410903 | P26: =E5 -> 7.9290858 | Q26: =E6 -> 10.754811 | R26: =(((760*22.4)*(273+J26))/(760*273)) -> 24.426667 | S26: =(((760*22.4)*(273+K26))/(760*273)) -> 24.689231 | T26: =(((760*22.4)*(273+L26))/(760*273)) -> 24.771282 | U26: =(((760*22.4)*(273+M26))/(760*273)) -> 24.820513 | V26: =((N26/(R26))*(0.016043)) -> 0.0023182264 | W26: =((O26/(S26))*(0.016043)) -> 0.0039254852 | X26: =((P26/(T26))*(0.016043)) -> 0.0051352337 | Y26: =((Q26/(U26))*(0.016043)) -> 0.0069514853
A27: RES | C27: 201 | D27: 0 | E27: 2.2342952 | F27: 0.34763335 | H27: 102 | J27: =J8 -> 26 | K27: =K8 -> 28.5 | L27: =L8 -> 29.4 | M27: =M8 -> 30.2 | N27: =E7 -> 2.378823 | O27: =E8 -> 3.4053826 | P27: =E9 -> 4.5042955 | Q27: =E10 -> 5.8722058 | R27: =(((760*22.4)*(273+J27))/(760*273)) -> 24.533333 | S27: =(((760*22.4)*(273+K27))/(760*273)) -> 24.738462 | T27: =(((760*22.4)*(273+L27))/(760*273)) -> 24.812308 | U27: =(((760*22.4)*(273+M27))/(760*273)) -> 24.877949 | V27: =((N27/(R27))*(0.016043)) -> 0.0015555757 | W27: =((O27/(S27))*(0.016043)) -> 0.0022084054 | X27: =((P27/(T27))*(0.016043)) -> 0.0029123616 | Y27: =((Q27/(U27))*(0.016043)) -> 0.0037867993
A28: RES | C28: 201 | D28: 21 | E28: 4.3900344 | F28: 0.34926784 | H28: 103 | J28: =J9 -> 25.4 | K28: =K9 -> 27.9 | L28: =L9 -> 29 | M28: =M9 -> 29.2 | N28: =E11 -> 2.3005595 | O28: =E12 -> 3.2219916 | P28: =E13 -> 4.1174552 | Q28: =E14 -> 4.999666 | R28: =(((760*22.4)*(273+J28))/(760*273)) -> 24.484103 | S28: =(((760*22.4)*(273+K28))/(760*273)) -> 24.689231 | T28: =(((760*22.4)*(273+L28))/(760*273)) -> 24.779487 | U28: =(((760*22.4)*(273+M28))/(760*273)) -> 24.795897 | V28: =((N28/(R28))*(0.016043)) -> 0.001507422 | W28: =((O28/(S28))*(0.016043)) -> 0.002093642 | X28: =((P28/(T28))*(0.016043)) -> 0.0026657668 | Y28: =((Q28/(U28))*(0.016043)) -> 0.0032347949
A29: RES | C29: 201 | D29: 42 | E29: 5.8770413 | F29: 0.35089211 | H29: 104 | J29: =J10 -> 25.6 | K29: =K10 -> 27.3 | L29: =L10 -> 29.3 | M29: =M10 -> 29.1 | N29: =E15 -> 2.286053 | O29: =E16 -> 2.2735165 | P29: =E17 -> 3.8686954 | Q29: =E18 -> 4.5023255 | R29: =(((760*22.4)*(273+J29))/(760*273)) -> 24.500513 | S29: =(((760*22.4)*(273+K29))/(760*273)) -> 24.64 | T29: =(((760*22.4)*(273+L29))/(760*273)) -> 24.804103 | U29: =(((760*22.4)*(273+M29))/(760*273)) -> 24.787692 | V29: =((N29/(R29))*(0.016043)) -> 0.0014969135 | W29: =((O29/(S29))*(0.016043)) -> 0.001480277 | X29: =((P29/(T29))*(0.016043)) -> 0.0025022264 | Y29: =((Q29/(U29))*(0.016043)) -> 0.0029139787
A30: RES | C30: 201 | D30: 63 | E30: 7.2524735 | F30: 0.36114852 | H30: 105 | J30: =J11 -> 25.9 | K30: =K11 -> 27.8 | L30: =L11 -> 29.4 | M30: =M11 -> 29.3 | N30: =E19 -> 2.7660215 | O30: =E20 -> 4.7129386 | P30: =E21 -> 6.3887092 | Q30: =E22 -> 7.9842464 | R30: =(((760*22.4)*(273+J30))/(760*273)) -> 24.525128 | S30: =(((760*22.4)*(273+K30))/(760*273)) -> 24.681026 | T30: =(((760*22.4)*(273+L30))/(760*273)) -> 24.812308 | U30: =(((760*22.4)*(273+M30))/(760*273)) -> 24.804103 | V30: =((N30/(R30))*(0.016043)) -> 0.0018093803 | W30: =((O30/(S30))*(0.016043)) -> 0.0030634737 | X30: =((P30/(T30))*(0.016043)) -> 0.0041307751 | Y30: =((Q30/(U30))*(0.016043)) -> 0.0051641161
A31: RES | C31: 202 | D31: 0 | E31: 2.2869485 | F31: 0.35848226 | H31: 106 | J31: =J12 -> 27.2 | K31: =K12 -> 28.8 | L31: =L12 -> 29.7 | M31: =M12 -> 29.2 | N31: =E23 -> 2.6082408 | O31: =E24 -> 4.1239026 | P31: =E25 -> 5.9062334 | Q31: =E26 -> 7.3722865 | R31: =(((760*22.4)*(273+J31))/(760*273)) -> 24.631795 | S31: =(((760*22.4)*(273+K31))/(760*273)) -> 24.763077 | T31: =(((760*22.4)*(273+L31))/(760*273)) -> 24.836923 | U31: =(((760*22.4)*(273+M31))/(760*273)) -> 24.795897 | V31: =((N31/(R31))*(0.016043)) -> 0.0016987803 | W31: =((O31/(S31))*(0.016043)) -> 0.0026717104 | X31: =((P31/(T31))*(0.016043)) -> 0.0038150339 | Y31: =((Q31/(U31))*(0.016043)) -> 0.0047698855
A32: RES | C32: 202 | D32: 21 | E32: 3.4707514 | F32: 0.34743925 | H32: 201 | J32: =J13 -> 25.8 | K32: =K13 -> 28 | L32: =L13 -> 28.9 | M32: =M13 -> 29.1 | N32: =E27 -> 2.2342952 | O32: =E28 -> 4.3900344 | P32: =E29 -> 5.8770413 | Q32: =E30 -> 7.2524735 | R32: =(((760*22.4)*(273+J32))/(760*273)) -> 24.516923 | S32: =(((760*22.4)*(273+K32))/(760*273)) -> 24.697436 | T32: =(((760*22.4)*(273+L32))/(760*273)) -> 24.771282 | U32: =(((760*22.4)*(273+M32))/(760*273)) -> 24.787692 | V32: =((N32/(R32))*(0.016043)) -> 0.0014620431 | W32: =((O32/(S32))*(0.016043)) -> 0.0028516856 | X32: =((P32/(T32))*(0.016043)) -> 0.0038062371 | Y32: =((Q32/(U32))*(0.016043)) -> 0.0046939195
A33: RES | C33: 202 | D33: 42 | E33: 4.4666861 | F33: 0.36318142 | H33: 202 | J33: =J14 -> 24.9 | K33: =K14 -> 30.5 | L33: =L14 -> 30.8 | M33: =M14 -> 34.3 | N33: =E31 -> 2.2869485 | O33: =E32 -> 3.4707514 | P33: =E33 -> 4.4666861 | Q33: =E34 -> 6.1188165 | R33: =(((760*22.4)*(273+J33))/(760*273)) -> 24.443077 | S33: =(((760*22.4)*(273+K33))/(760*273)) -> 24.902564 | T33: =(((760*22.4)*(273+L33))/(760*273)) -> 24.927179 | U33: =(((760*22.4)*(273+M33))/(760*273)) -> 25.214359 | V33: =((N33/(R33))*(0.016043)) -> 0.0015010186 | W33: =((O33/(S33))*(0.016043)) -> 0.0022359651 | X33: =((P33/(T33))*(0.016043)) -> 0.0028747354 | Y33: =((Q33/(U33))*(0.016043)) -> 0.0038931854
A34: RES | C34: 202 | D34: 63 | E34: 6.1188165 | F34: 0.36280344 | H34: 203 | J34: =J15 -> 25 | K34: =K15 -> 28.4 | L34: =L15 -> 29.5 | M34: =M15 -> 29.8 | N34: =E35 -> 2.3258116 | O34: =E36 -> 2.5865706 | P34: =E37 -> 2.9383087 | Q34: =E38 -> 3.3838914 | R34: =(((760*22.4)*(273+J34))/(760*273)) -> 24.451282 | S34: =(((760*22.4)*(273+K34))/(760*273)) -> 24.730256 | T34: =(((760*22.4)*(273+L34))/(760*273)) -> 24.820513 | U34: =(((760*22.4)*(273+M34))/(760*273)) -> 24.845128 | V34: =((N34/(R34))*(0.016043)) -> 0.0015260139 | W34: =((O34/(S34))*(0.016043)) -> 0.0016779588 | X34: =((P34/(T34))*(0.016043)) -> 0.0018992068 | Y34: =((Q34/(U34))*(0.016043)) -> 0.0021850469
A35: RES | C35: 203 | D35: 0 | E35: 2.3258116 | F35: 0.35772631 | H35: 204 | J35: =J16 -> 24.7 | K35: =K16 -> 28 | L35: =L16 -> 29.3 | M35: =M16 -> 29.6 | N35: =E39 -> 2.2353697 | O35: =E40 -> 3.2934496 | P35: =E41 -> 4.4339121 | Q35: =E42 -> 5.6669655 | R35: =(((760*22.4)*(273+J35))/(760*273)) -> 24.426667 | S35: =(((760*22.4)*(273+K35))/(760*273)) -> 24.697436 | T35: =(((760*22.4)*(273+L35))/(760*273)) -> 24.804103 | U35: =(((760*22.4)*(273+M35))/(760*273)) -> 24.828718 | V35: =((N35/(R35))*(0.016043)) -> 0.0014681511 | W35: =((O35/(S35))*(0.016043)) -> 0.0021393643 | X35: =((P35/(T35))*(0.016043)) -> 0.0028678019 | Y35: =((Q35/(U35))*(0.016043)) -> 0.0036616924
A36: RES | C36: 203 | D36: 21 | E36: 2.5865706 | F36: 0.36167973 | H36: 205 | J36: =J17 -> 24.9 | K36: =K17 -> 28.8 | L36: =L17 -> 30 | M36: =M17 -> 30.7 | N36: =E43 -> 2.3480191 | O36: =E44 -> 2.6479994 | P36: =E45 -> 3.1619955 | Q36: =E46 -> 3.6414268 | R36: =(((760*22.4)*(273+J36))/(760*273)) -> 24.443077 | S36: =(((760*22.4)*(273+K36))/(760*273)) -> 24.763077 | T36: =(((760*22.4)*(273+L36))/(760*273)) -> 24.861538 | U36: =(((760*22.4)*(273+M36))/(760*273)) -> 24.918974 | V36: =((N36/(R36))*(0.016043)) -> 0.0015411018 | W36: =((O36/(S36))*(0.016043)) -> 0.0017155321 | X36: =((P36/(T36))*(0.016043)) -> 0.0020404165 | Y36: =((Q36/(U36))*(0.016043)) -> 0.0023443746
A37: RES | C37: 203 | D37: 42 | E37: 2.9383087 | F37: 0.36000438 | H37: 206 | J37: =J18 -> 24.9 | K37: =K18 -> 27.8 | L37: =L18 -> 28.8 | M37: =M18 -> 30.1 | N37: =E47 -> 2.0999756 | O37: =E48 -> 2.830674 | P37: =E49 -> 3.3229999 | Q37: =E50 -> 4.1120825 | R37: =(((760*22.4)*(273+J37))/(760*273)) -> 24.443077 | S37: =(((760*22.4)*(273+K37))/(760*273)) -> 24.681026 | T37: =(((760*22.4)*(273+L37))/(760*273)) -> 24.763077 | U37: =(((760*22.4)*(273+M37))/(760*273)) -> 24.869744 | V37: =((N37/(R37))*(0.016043)) -> 0.0013783007 | W37: =((O37/(S37))*(0.016043)) -> 0.0018399763 | X37: =((P37/(T37))*(0.016043)) -> 0.0021528378 | Y37: =((Q37/(U37))*(0.016043)) -> 0.0026526264
A38: RES | C38: 203 | D38: 63 | E38: 3.3838914 | F38: 0.35913606
A39: RES | C39: 204 | D39: 0 | E39: 2.2353697 | F39: 0.35938123
A40: RES | C40: 204 | D40: 21 | E40: 3.2934496 | F40: 0.36131197
...

Sheet Flux data
C1: Time interval, min
C2: 0 | D2: 21 | E2: 42 | F2: 63
A3: N2O
C4: N2O concentration, mg L-1 | G4: Detection test | H4: RSQ_lin | I4: Linearity test | J4: Slope | K4: Headspace volume, L | L4: Area covered, m2
A5: Plot | M5: N2O efflux
B6: Trt | C6: 0 | D6: 21 | E6: 42 | F6: 63 | M6: mg m-2 min-1 | N6: mg m-2 hr-1 | O6: g ha-1 d-1
A8: 101 | C8: ='GC rawdata'!V7 -> 0.0005997042 | D8: ='GC rawdata'!W7 -> 0.00060186767 | E8: ='GC rawdata'!X7 -> 0.00061107333 | F8: ='GC rawdata'!Y7 -> 0.00062034996 | G8: =+IF((ABS(F8-C8))>0.000183,"PASS","FAIL") -> FAIL | H8: =+RSQ(C8:F8,$C$2:$F$2) -> 0.94376496 | I8: =IF(H8>0.845,"LIN","MISS") -> LIN | J8: =IF(G8="FAIL","0",IF(I8="LIN",+SLOPE(C8:F8,$C$2:$F$2),"MISS")) -> 0 | K8: ='Field data'!K10 -> 19.889639 | L8: ='Field data'!L10*0.0001 -> 0.068349275 | M8: =IF(J8="MISS","MISS",((K8/L8)*J8)) -> 0 | N8: =IF(M8="MISS","MISS",M8*60) -> 0 | O8: =IF(N8="MISS","MISS",N8*240) -> 0
A9: 102 | C9: ='GC rawdata'!V8 -> 0.00061214342 | D9: ='GC rawdata'!W8 -> 0.00061471938 | E9: ='GC rawdata'!X8 -> 0.00061334288 | F9: ='GC rawdata'!Y8 -> 0.00063798511 | G9: =+IF((ABS(F9-C9))>0.000183,"PASS","FAIL") -> FAIL | H9: =+RSQ(C9:F9,$C$2:$F$2) -> 0.63501285 | I9: =IF(H9>0.845,"LIN","MISS") -> MISS | J9: =IF(G9="FAIL","0",IF(I9="LIN",+SLOPE(C9:F9,$C$2:$F$2),"MISS")) -> 0 | K9: ='Field data'!K11 -> 17.514502 | L9: ='Field data'!L11*0.0001 -> 0.068349275 | M9: =IF(J9="MISS","MISS",((K9/L9)*J9)) -> 0 | N9: =IF(M9="MISS","MISS",M9*60) -> 0 | O9: =IF(N9="MISS","MISS",N9*240) -> 0
A10: 103 | C10: ='GC rawdata'!V9 -> 0.00062775332 | D10: ='GC rawdata'!W9 -> 0.00064448252 | E10: ='GC rawdata'!X9 -> 0.00063262701 | F10: ='GC rawdata'!Y9 -> 0.0006414925 | G10: =+IF((ABS(F10-C10))>0.000183,"PASS","FAIL") -> FAIL | H10: =+RSQ(C10:F10,$C$2:$F$2) -> 0.23932243 | I10: =IF(H10>0.845,"LIN","MISS") -> MISS | J10: =IF(G10="FAIL","0",IF(I10="LIN",+SLOPE(C10:F10,$C$2:$F$2),"MISS")) -> 0 | K10: ='Field data'!K12 -> 18.8644 | L10: ='Field data'!L12*0.0001 -> 0.068349275 | M10: =IF(J10="MISS","MISS",((K10/L10)*J10)) -> 0 | N10: =IF(M10="MISS","MISS",M10*60) -> 0 | O10: =IF(N10="MISS","MISS",N10*240) -> 0
A11: 104 | C11: ='GC rawdata'!V10 -> 0.00064627187 | D11: ='GC rawdata'!W10 -> 0.00073817738 | E11: ='GC rawdata'!X10 -> 0.00064863991 | F11: ='GC rawdata'!Y10 -> 0.00066163975 | G11: =+IF((ABS(F11-C11))>0.000183,"PASS","FAIL") -> FAIL | H11: =+RSQ(C11:F11,$C$2:$F$2) -> 0.016597444 | I11: =IF(H11>0.845,"LIN","MISS") -> MISS | J11: =IF(G11="FAIL","0",IF(I11="LIN",+SLOPE(C11:F11,$C$2:$F$2),"MISS")) -> 0 | K11: ='Field data'!K13 -> 20.060512 | L11: ='Field data'!L13*0.0001 -> 0.068349275 | M11: =IF(J11="MISS","MISS",((K11/L11)*J11)) -> 0 | N11: =IF(M11="MISS","MISS",M11*60) -> 0 | O11: =IF(N11="MISS","MISS",N11*240) -> 0
A12: 105 | C12: ='GC rawdata'!V11 -> 0.00057813822 | D12: ='GC rawdata'!W11 -> 0.0006144739 | E12: ='GC rawdata'!X11 -> 0.00062050074 | F12: ='GC rawdata'!Y11 -> 0.00063305057 | G12: =+IF((ABS(F12-C12))>0.000183,"PASS","FAIL") -> FAIL | H12: =+RSQ(C12:F12,$C$2:$F$2) -> 0.87448424 | I12: =IF(H12>0.845,"LIN","MISS") -> LIN | J12: =IF(G12="FAIL","0",IF(I12="LIN",+SLOPE(C12:F12,$C$2:$F$2),"MISS")) -> 0 | K12: ='Field data'!K14 -> 18.8644 | L12: ='Field data'!L14*0.0001 -> 0.068349275 | M12: =IF(J12="MISS","MISS",((K12/L12)*J12)) -> 0 | N12: =IF(M12="MISS","MISS",M12*60) -> 0 | O12: =IF(N12="MISS","MISS",N12*240) -> 0
A13: 106 | C13: ='GC rawdata'!V12 -> 0.00061661472 | D13: ='GC rawdata'!W12 -> 0.00059604194 | E13: ='GC rawdata'!X12 -> 0.00060368342 | F13: ='GC rawdata'!Y12 -> 0.0006326254 | G13: =+IF((ABS(F13-C13))>0.000183,"PASS","FAIL") -> FAIL | H13: =+RSQ(C13:F13,$C$2:$F$2) -> 0.20119176 | I13: =IF(H13>0.845,"LIN","MISS") -> MISS | J13: =IF(G13="FAIL","0",IF(I13="LIN",+SLOPE(C13:F13,$C$2:$F$2),"MISS")) -> 0 | K13: ='Field data'!K15 -> 18.693527 | L13: ='Field data'!L15*0.0001 -> 0.068349275 | M13: =IF(J13="MISS","MISS",((K13/L13)*J13)) -> 0 | N13: =IF(M13="MISS","MISS",M13*60) -> 0 | O13: =IF(N13="MISS","MISS",N13*240) -> 0
A14: 201 | C14: ='GC rawdata'!V13 -> 0.00062408868 | D14: ='GC rawdata'!W13 -> 0.0006224401 | E14: ='GC rawdata'!X13 -> 0.00062347057 | F14: ='GC rawdata'!Y13 -> 0.0006412695 | G14: =+IF((ABS(F14-C14))>0.000183,"PASS","FAIL") -> FAIL | H14: =+RSQ(C14:F14,$C$2:$F$2) -> 0.56947347 | I14: =IF(H14>0.845,"LIN","MISS") -> MISS | J14: =IF(G14="FAIL","0",IF(I14="LIN",+SLOPE(C14:F14,$C$2:$F$2),"MISS")) -> 0 | K14: ='Field data'!K16 -> 18.949837 | L14: ='Field data'!L16*0.0001 -> 0.068349275 | M14: =IF(J14="MISS","MISS",((K14/L14)*J14)) -> 0 | N14: =IF(M14="MISS","MISS",M14*60) -> 0 | O14: =IF(N14="MISS","MISS",N14*240) -> 0
A15: 202 | C15: ='GC rawdata'!V14 -> 0.0006455095 | D15: ='GC rawdata'!W14 -> 0.00061408099 | E15: ='GC rawdata'!X14 -> 0.00064127059 | F15: ='GC rawdata'!Y14 -> 0.00063330703 | G15: =+IF((ABS(F15-C15))>0.000183,"PASS","FAIL") -> FAIL | H15: =+RSQ(C15:F15,$C$2:$F$2) -> 0.0076233105 | I15: =IF(H15>0.845,"LIN","MISS") -> MISS | J15: =IF(G15="FAIL","0",IF(I15="LIN",+SLOPE(C15:F15,$C$2:$F$2),"MISS")) -> 0 | K15: ='Field data'!K17 -> 20.145949 | L15: ='Field data'!L17*0.0001 -> 0.068349275 | M15: =IF(J15="MISS","MISS",((K15/L15)*J15)) -> 0 | N15: =IF(M15="MISS","MISS",M15*60) -> 0 | O15: =IF(N15="MISS","MISS",N15*240) -> 0
A16: 203 | C16: ='GC rawdata'!V15 -> 0.00064393212 | D16: ='GC rawdata'!W15 -> 0.00064370427 | E16: ='GC rawdata'!X15 -> 0.00063839265 | F16: ='GC rawdata'!Y15 -> 0.0006362219 | G16: =+IF((ABS(F16-C16))>0.000183,"PASS","FAIL") -> FAIL | H16: =+RSQ(C16:F16,$C$2:$F$2) -> 0.90338271 | I16: =IF(H16>0.845,"LIN","MISS") -> LIN | J16: =IF(G16="FAIL","0",IF(I16="LIN",+SLOPE(C16:F16,$C$2:$F$2),"MISS")) -> 0 | K16: ='Field data'!K18 -> 20.402259 | L16: ='Field data'!L18*0.0001 -> 0.068349275 | M16: =IF(J16="MISS","MISS",((K16/L16)*J16)) -> 0 | N16: =IF(M16="MISS","MISS",M16*60) -> 0 | O16: =IF(N16="MISS","MISS",N16*240) -> 0
A17: 204 | C17: ='GC rawdata'!V16 -> 0.000647563 | D17: ='GC rawdata'!W16 -> 0.0006439043 | E17: ='GC rawdata'!X16 -> 0.00064459756 | F17: ='GC rawdata'!Y16 -> 0.00063823601 | G17: =+IF((ABS(F17-C17))>0.000183,"PASS","FAIL") -> FAIL | H17: =+RSQ(C17:F17,$C$2:$F$2) -> 0.81713091 | I17: =IF(H17>0.845,"LIN","MISS") -> MISS | J17: =IF(G17="FAIL","0",IF(I17="LIN",+SLOPE(C17:F17,$C$2:$F$2),"MISS")) -> 0 | K17: ='Field data'!K19 -> 21.256625 | L17: ='Field data'!L19*0.0001 -> 0.068349275 | M17: =IF(J17="MISS","MISS",((K17/L17)*J17)) -> 0 | N17: =IF(M17="MISS","MISS",M17*60) -> 0 | O17: =IF(N17="MISS","MISS",N17*240) -> 0
A18: 205 | C18: ='GC rawdata'!V17 -> 0.00066136588 | D18: ='GC rawdata'!W17 -> 0.00063678663 | E18: ='GC rawdata'!X17 -> 0.00064129987 | F18: ='GC rawdata'!Y17 -> 0.00065308376 | G18: =+IF((ABS(F18-C18))>0.000183,"PASS","FAIL") -> FAIL | H18: =+RSQ(C18:F18,$C$2:$F$2) -> 0.055117403 | I18: =IF(H18>0.845,"LIN","MISS") -> MISS | J18: =IF(G18="FAIL","0",IF(I18="LIN",+SLOPE(C18:F18,$C$2:$F$2),"MISS")) -> 0 | K18: ='Field data'!K20 -> 21.256625 | L18: ='Field data'!L20*0.0001 -> 0.068349275 | M18: =IF(J18="MISS","MISS",((K18/L18)*J18)) -> 0 | N18: =IF(M18="MISS","MISS",M18*60) -> 0 | O18: =IF(N18="MISS","MISS",N18*240) -> 0
A19: 206 | C19: ='GC rawdata'!V18 -> 0.00066394117 | D19: ='GC rawdata'!W18 -> 0.00064152693 | E19: ='GC rawdata'!X18 -> 0.00064673676 | F19: ='GC rawdata'!Y18 -> 0.00065202626 | G19: =+IF((ABS(F19-C19))>0.000183,"PASS","FAIL") -> FAIL | H19: =+RSQ(C19:F19,$C$2:$F$2) -> 0.16864797 | I19: =IF(H19>0.845,"LIN","MISS") -> MISS | J19: =IF(G19="FAIL","0",IF(I19="LIN",+SLOPE(C19:F19,$C$2:$F$2),"MISS")) -> 0 | K19: ='Field data'!K21 -> 21.017402 | L19: ='Field data'!L21*0.0001 -> 0.068349275 | M19: =IF(J19="MISS","MISS",((K19/L19)*J19)) -> 0 | N19: =IF(M19="MISS","MISS",M19*60) -> 0 | O19: =IF(N19="MISS","MISS",N19*240) -> 0
A23: CH4
C24: CH4 concentration, mg L-1 | G24: Detection test | H24: RSQ_lin | I24: Linearity test | J24: Slope | K24: Headspace volume, L | L24: Area covered, m2
A25: Plot | M25: CH4 efflux
B26: Trt | C26: 0 | D26: 21 | E26: 42 | F26: 63 | M26: mg m-2 min-1 | N26: mg m-2 hr-1 | O26: g ha-1 d-1
A28: 101 | C28: ='GC rawdata'!V26 -> 0.0023182264 | D28: ='GC rawdata'!W26 -> 0.0039254852 | E28: ='GC rawdata'!X26 -> 0.0051352337 | F28: ='GC rawdata'!Y26 -> 0.0069514853 | G28: =+IF((ABS(F28-C28))>0.000183,"PASS","FAIL") -> PASS | H28: =+RSQ(C28:F28,$C$2:$F$2) -> 0.99465663 | I28: =IF(H28>0.845,"LIN","MISS") -> LIN | J28: =IF(G28="FAIL","0",IF(I28="LIN",+SLOPE(C28:F28,$C$2:$F$2),"MISS")) -> 7.1950121e-05 | K28: ='Field data'!K10 -> 19.889639 | L28: ='Field data'!L10*0.0001 -> 0.068349275 | M28: =IF(J28="MISS","MISS",((K28/L28)*J28)) -> 0.020937485 | N28: =IF(M28="MISS","MISS",M28*60) -> 1.2562491 | O28: =IF(N28="MISS","MISS",N28*240) -> 301.49979
A29: 102 | C29: ='GC rawdata'!V27 -> 0.0015555757 | D29: ='GC rawdata'!W27 -> 0.0022084054 | E29: ='GC rawdata'!X27 -> 0.0029123616 | F29: ='GC rawdata'!Y27 -> 0.0037867993 | G29: =+IF((ABS(F29-C29))>0.000183,"PASS","FAIL") -> PASS | H29: =+RSQ(C29:F29,$C$2:$F$2) -> 0.99527512 | I29: =IF(H29>0.845,"LIN","MISS") -> LIN | J29: =IF(G29="FAIL","0",IF(I29="LIN",+SLOPE(C29:F29,$C$2:$F$2),"MISS")) -> 3.5226794e-05 | K29: ='Field data'!K11 -> 17.514502 | L29: ='Field data'!L11*0.0001 -> 0.068349275 | M29: =IF(J29="MISS","MISS",((K29/L29)*J29)) -> 0.0090268661 | N29: =IF(M29="MISS","MISS",M29*60) -> 0.54161197 | O29: =IF(N29="MISS","MISS",N29*240) -> 129.98687
A30: 103 | C30: ='GC rawdata'!V28 -> 0.001507422 | D30: ='GC rawdata'!W28 -> 0.002093642 | E30: ='GC rawdata'!X28 -> 0.0026657668 | F30: ='GC rawdata'!Y28 -> 0.0032347949 | G30: =+IF((ABS(F30-C30))>0.000183,"PASS","FAIL") -> PASS | H30: =+RSQ(C30:F30,$C$2:$F$2) -> 0.99995172 | I30: =IF(H30>0.845,"LIN","MISS") -> LIN | J30: =IF(G30="FAIL","0",IF(I30="LIN",+SLOPE(C30:F30,$C$2:$F$2),"MISS")) -> 2.7401158e-05 | K30: ='Field data'!K12 -> 18.8644 | L30: ='Field data'!L12*0.0001 -> 0.068349275 | M30: =IF(J30="MISS","MISS",((K30/L30)*J30)) -> 0.0075627197 | N30: =IF(M30="MISS","MISS",M30*60) -> 0.45376318 | O30: =IF(N30="MISS","MISS",N30*240) -> 108.90316
A31: 104 | C31: ='GC rawdata'!V29 -> 0.0014969135 | D31: ='GC rawdata'!W29 -> 0.001480277 | E31: ='GC rawdata'!X29 -> 0.0025022264 | F31: ='GC rawdata'!Y29 -> 0.0029139787 | G31: =+IF((ABS(F31-C31))>0.000183,"PASS","FAIL") -> PASS | H31: =+RSQ(C31:F31,$C$2:$F$2) -> 0.88435674 | I31: =IF(H31>0.845,"LIN","MISS") -> LIN | J31: =IF(G31="FAIL","0",IF(I31="LIN",+SLOPE(C31:F31,$C$2:$F$2),"MISS")) -> 2.5110215e-05 | K31: ='Field data'!K13 -> 20.060512 | L31: ='Field data'!L13*0.0001 -> 0.068349275 | M31: =IF(J31="MISS","MISS",((K31/L31)*J31)) -> 0.0073698481 | N31: =IF(M31="MISS","MISS",M31*60) -> 0.44219089 | O31: =IF(N31="MISS","MISS",N31*240) -> 106.12581
A32: 105 | C32: ='GC rawdata'!V30 -> 0.0018093803 | D32: ='GC rawdata'!W30 -> 0.0030634737 | E32: ='GC rawdata'!X30 -> 0.0041307751 | F32: ='GC rawdata'!Y30 -> 0.0051641161 | G32: =+IF((ABS(F32-C32))>0.000183,"PASS","FAIL") -> PASS | H32: =+RSQ(C32:F32,$C$2:$F$2) -> 0.99784972 | I32: =IF(H32>0.845,"LIN","MISS") -> LIN | J32: =IF(G32="FAIL","0",IF(I32="LIN",+SLOPE(C32:F32,$C$2:$F$2),"MISS")) -> 5.3007185e-05 | K32: ='Field data'!K14 -> 18.8644 | L32: ='Field data'!L14*0.0001 -> 0.068349275 | M32: =IF(J32="MISS","MISS",((K32/L32)*J32)) -> 0.014629983 | N32: =IF(M32="MISS","MISS",M32*60) -> 0.87779898 | O32: =IF(N32="MISS","MISS",N32*240) -> 210.67175
A33: 106 | C33: ='GC rawdata'!V31 -> 0.0016987803 | D33: ='GC rawdata'!W31 -> 0.0026717104 | E33: ='GC rawdata'!X31 -> 0.0038150339 | F33: ='GC rawdata'!Y31 -> 0.0047698855 | G33: =+IF((ABS(F33-C33))>0.000183,"PASS","FAIL") -> PASS | H33: =+RSQ(C33:F33,$C$2:$F$2) -> 0.99878557 | I33: =IF(H33>0.845,"LIN","MISS") -> LIN | J33: =IF(G33="FAIL","0",IF(I33="LIN",+SLOPE(C33:F33,$C$2:$F$2),"MISS")) -> 4.931733e-05 | K33: ='Field data'!K15 -> 18.693527 | L33: ='Field data'!L15*0.0001 -> 0.068349275 | M33: =IF(J33="MISS","MISS",((K33/L33)*J33)) -> 0.01348829 | N33: =IF(M33="MISS","MISS",M33*60) -> 0.80929738 | O33: =IF(N33="MISS","MISS",N33*240) -> 194.23137
A34: 201 | C34: ='GC rawdata'!V32 -> 0.0014620431 | D34: ='GC rawdata'!W32 -> 0.0028516856 | E34: ='GC rawdata'!X32 -> 0.0038062371 | F34: ='GC rawdata'!Y32 -> 0.0046939195 | G34: =+IF((ABS(F34-C34))>0.000183,"PASS","FAIL") -> PASS | H34: =+RSQ(C34:F34,$C$2:$F$2) -> 0.98784719 | I34: =IF(H34>0.845,"LIN","MISS") -> LIN | J34: =IF(G34="FAIL","0",IF(I34="LIN",+SLOPE(C34:F34,$C$2:$F$2),"MISS")) -> 5.0715147e-05 | K34: ='Field data'!K16 -> 18.949837 | L34: ='Field data'!L16*0.0001 -> 0.068349275 | M34: =IF(J34="MISS","MISS",((K34/L34)*J34)) -> 0.014060774 | N34: =IF(M34="MISS","MISS",M34*60) -> 0.84364646 | O34: =IF(N34="MISS","MISS",N34*240) -> 202.47515
A35: 202 | C35: ='GC rawdata'!V33 -> 0.0015010186 | D35: ='GC rawdata'!W33 -> 0.0022359651 | E35: ='GC rawdata'!X33 -> 0.0028747354 | F35: ='GC rawdata'!Y33 -> 0.0038931854 | G35: =+IF((ABS(F35-C35))>0.000183,"PASS","FAIL") -> PASS | H35: =+RSQ(C35:F35,$C$2:$F$2) -> 0.98981781 | I35: =IF(H35>0.845,"LIN","MISS") -> LIN | J35: =IF(G35="FAIL","0",IF(I35="LIN",+SLOPE(C35:F35,$C$2:$F$2),"MISS")) -> 3.7215573e-05 | K35: ='Field data'!K17 -> 20.145949 | L35: ='Field data'!L17*0.0001 -> 0.068349275 | M35: =IF(J35="MISS","MISS",((K35/L35)*J35)) -> 0.01096929 | N35: =IF(M35="MISS","MISS",M35*60) -> 0.65815741 | O35: =IF(N35="MISS","MISS",N35*240) -> 157.95778
A36: 203 | C36: ='GC rawdata'!V34 -> 0.0015260139 | D36: ='GC rawdata'!W34 -> 0.0016779588 | E36: ='GC rawdata'!X34 -> 0.0018992068 | F36: ='GC rawdata'!Y34 -> 0.0021850469 | G36: =+IF((ABS(F36-C36))>0.000183,"PASS","FAIL") -> PASS | H36: =+RSQ(C36:F36,$C$2:$F$2) -> 0.98178493 | I36: =IF(H36>0.845,"LIN","MISS") -> LIN | J36: =IF(G36="FAIL","0",IF(I36="LIN",+SLOPE(C36:F36,$C$2:$F$2),"MISS")) -> 1.0468319e-05 | K36: ='Field data'!K18 -> 20.402259 | L36: ='Field data'!L18*0.0001 -> 0.068349275 | M36: =IF(J36="MISS","MISS",((K36/L36)*J36)) -> 0.0031247934 | N36: =IF(M36="MISS","MISS",M36*60) -> 0.1874876 | O36: =IF(N36="MISS","MISS",N36*240) -> 44.997024
A37: 204 | C37: ='GC rawdata'!V35 -> 0.0014681511 | D37: ='GC rawdata'!W35 -> 0.0021393643 | E37: ='GC rawdata'!X35 -> 0.0028678019 | F37: ='GC rawdata'!Y35 -> 0.0036616924 | G37: =+IF((ABS(F37-C37))>0.000183,"PASS","FAIL") -> PASS | H37: =+RSQ(C37:F37,$C$2:$F$2) -> 0.99859216 | I37: =IF(H37>0.845,"LIN","MISS") -> LIN | J37: =IF(G37="FAIL","0",IF(I37="LIN",+SLOPE(C37:F37,$C$2:$F$2),"MISS")) -> 3.4805055e-05 | K37: ='Field data'!K19 -> 21.256625 | L37: ='Field data'!L19*0.0001 -> 0.068349275 | M37: =IF(J37="MISS","MISS",((K37/L37)*J37)) -> 0.010824372 | N37: =IF(M37="MISS","MISS",M37*60) -> 0.64946233 | O37: =IF(N37="MISS","MISS",N37*240) -> 155.87096
A38: 205 | C38: ='GC rawdata'!V36 -> 0.0015411018 | D38: ='GC rawdata'!W36 -> 0.0017155321 | E38: ='GC rawdata'!X36 -> 0.0020404165 | F38: ='GC rawdata'!Y36 -> 0.0023443746 | G38: =+IF((ABS(F38-C38))>0.000183,"PASS","FAIL") -> PASS | H38: =+RSQ(C38:F38,$C$2:$F$2) -> 0.9850816 | I38: =IF(H38>0.845,"LIN","MISS") -> LIN | J38: =IF(G38="FAIL","0",IF(I38="LIN",+SLOPE(C38:F38,$C$2:$F$2),"MISS")) -> 1.3022394e-05 | K38: ='Field data'!K20 -> 21.256625 | L38: ='Field data'!L20*0.0001 -> 0.068349275 | M38: =IF(J38="MISS","MISS",((K38/L38)*J38)) -> 0.0040499644 | N38: =IF(M38="MISS","MISS",M38*60) -> 0.24299787 | O38: =IF(N38="MISS","MISS",N38*240) -> 58.319488
A39: 206 | C39: ='GC rawdata'!V37 -> 0.0013783007 | D39: ='GC rawdata'!W37 -> 0.0018399763 | E39: ='GC rawdata'!X37 -> 0.0021528378 | F39: ='GC rawdata'!Y37 -> 0.0026526264 | G39: =+IF((ABS(F39-C39))>0.000183,"PASS","FAIL") -> PASS | H39: =+RSQ(C39:F39,$C$2:$F$2) -> 0.9930343 | I39: =IF(H39>0.845,"LIN","MISS") -> LIN | J39: =IF(G39="FAIL","0",IF(I39="LIN",+SLOPE(C39:F39,$C$2:$F$2),"MISS")) -> 1.969447e-05 | K39: ='Field data'!K21 -> 21.017402 | L39: ='Field data'!L21*0.0001 -> 0.068349275 | M39: =IF(J39="MISS","MISS",((K39/L39)*J39)) -> 0.0060560495 | N39: =IF(M39="MISS","MISS",M39*60) -> 0.36336297 | O39: =IF(N39="MISS","MISS",N39*240) -> 87.207113
